appending output to nohup.out
[04/Jan/2017 09:52:21] "GET /api/tfs/searchName/nodename?format=json&uinput= HTTP/1.1" 200 550
[04/Jan/2017 09:52:24] "GET /api/tfs/searchName/nodename?format=json&uinput= HTTP/1.1" 200 550
[04/Jan/2017 09:52:41] "POST /queryapp/ HTTP/1.1" 200 1870118
[04/Jan/2017 09:52:50] "GET /static/queryBuilder/2017-01-04T145229868Z468_cy.json HTTP/1.1" 200 8471
[04/Jan/2017 10:36:46] "GET /api/tfs/searchName/nodename?format=json&uinput= HTTP/1.1" 200 550
[04/Jan/2017 10:36:54] "POST /queryapp/ HTTP/1.1" 200 790606
[04/Jan/2017 10:41:34] "GET /api/tfs/searchName/nodename?format=json&uinput= HTTP/1.1" 200 550
[04/Jan/2017 10:41:42] "POST /queryapp/ HTTP/1.1" 200 570334
Unhandled exception in thread started by <function wrapper at 0x112da1c80>
Traceback (most recent call last):
  File "/Library/Python/2.7/site-packages/django/utils/autoreload.py", line 226, in wrapper
    fn(*args, **kwargs)
  File "/Library/Python/2.7/site-packages/django/core/management/commands/runserver.py", line 109, in inner_run
    autoreload.raise_last_exception()
  File "/Library/Python/2.7/site-packages/django/utils/autoreload.py", line 249, in raise_last_exception
    six.reraise(*_exception)
  File "/Library/Python/2.7/site-packages/django/utils/autoreload.py", line 226, in wrapper
    fn(*args, **kwargs)
  File "/Library/Python/2.7/site-packages/django/__init__.py", line 18, in setup
    apps.populate(settings.INSTALLED_APPS)
  File "/Library/Python/2.7/site-packages/django/apps/registry.py", line 115, in populate
    app_config.ready()
  File "/Library/Python/2.7/site-packages/debug_toolbar/apps.py", line 15, in ready
    dt_settings.patch_all()
  File "/Library/Python/2.7/site-packages/debug_toolbar/settings.py", line 243, in patch_all
    patch_root_urlconf()
  File "/Library/Python/2.7/site-packages/debug_toolbar/settings.py", line 231, in patch_root_urlconf
    reverse('djdt:render_panel')
  File "/Library/Python/2.7/site-packages/django/core/urlresolvers.py", line 568, in reverse
    app_list = resolver.app_dict[ns]
  File "/Library/Python/2.7/site-packages/django/core/urlresolvers.py", line 360, in app_dict
    self._populate()
  File "/Library/Python/2.7/site-packages/django/core/urlresolvers.py", line 293, in _populate
    for pattern in reversed(self.url_patterns):
  File "/Library/Python/2.7/site-packages/django/utils/functional.py", line 33, in __get__
    res = instance.__dict__[self.name] = self.func(instance)
  File "/Library/Python/2.7/site-packages/django/core/urlresolvers.py", line 417, in url_patterns
    patterns = getattr(self.urlconf_module, "urlpatterns", self.urlconf_module)
  File "/Library/Python/2.7/site-packages/django/utils/functional.py", line 33, in __get__
    res = instance.__dict__[self.name] = self.func(instance)
  File "/Library/Python/2.7/site-packages/django/core/urlresolvers.py", line 410, in urlconf_module
    return import_module(self.urlconf_name)
  File "/System/Library/Frameworks/Python.framework/Versions/2.7/lib/python2.7/importlib/__init__.py", line 37, in import_module
    __import__(name)
  File "/Users/Reetu/Documents/Projects/TargetDB/tgdbbackend/config/urls.py", line 27, in <module>
    url(r'^queryapp/', include('tgdbbackend.queryapp.urls', namespace='queryapp')),
  File "/Library/Python/2.7/site-packages/django/conf/urls/__init__.py", line 52, in include
    urlconf_module = import_module(urlconf_module)
  File "/System/Library/Frameworks/Python.framework/Versions/2.7/lib/python2.7/importlib/__init__.py", line 37, in import_module
    __import__(name)
  File "/Users/Reetu/Documents/Projects/TargetDB/tgdbbackend/tgdbbackend/queryapp/urls.py", line 4, in <module>
    from tgdbbackend.queryapp import views;
  File "/Users/Reetu/Documents/Projects/TargetDB/tgdbbackend/tgdbbackend/queryapp/views.py", line 7, in <module>
    from .app import query_TargetDB;
  File "/Users/Reetu/Documents/Projects/TargetDB/tgdbbackend/tgdbbackend/queryapp/app/query_TargetDB.py", line 36, in <module>
    from pathlib import Path
ImportError: No module named pathlib
Unhandled exception in thread started by <function wrapper at 0x1058e7c80>
Traceback (most recent call last):
  File "/Library/Python/2.7/site-packages/django/utils/autoreload.py", line 226, in wrapper
    fn(*args, **kwargs)
  File "/Library/Python/2.7/site-packages/django/core/management/commands/runserver.py", line 109, in inner_run
    autoreload.raise_last_exception()
  File "/Library/Python/2.7/site-packages/django/utils/autoreload.py", line 249, in raise_last_exception
    six.reraise(*_exception)
  File "/Library/Python/2.7/site-packages/django/utils/autoreload.py", line 226, in wrapper
    fn(*args, **kwargs)
  File "/Library/Python/2.7/site-packages/django/__init__.py", line 18, in setup
    apps.populate(settings.INSTALLED_APPS)
  File "/Library/Python/2.7/site-packages/django/apps/registry.py", line 115, in populate
    app_config.ready()
  File "/Library/Python/2.7/site-packages/debug_toolbar/apps.py", line 15, in ready
    dt_settings.patch_all()
  File "/Library/Python/2.7/site-packages/debug_toolbar/settings.py", line 243, in patch_all
    patch_root_urlconf()
  File "/Library/Python/2.7/site-packages/debug_toolbar/settings.py", line 231, in patch_root_urlconf
    reverse('djdt:render_panel')
  File "/Library/Python/2.7/site-packages/django/core/urlresolvers.py", line 568, in reverse
    app_list = resolver.app_dict[ns]
  File "/Library/Python/2.7/site-packages/django/core/urlresolvers.py", line 360, in app_dict
    self._populate()
  File "/Library/Python/2.7/site-packages/django/core/urlresolvers.py", line 293, in _populate
    for pattern in reversed(self.url_patterns):
  File "/Library/Python/2.7/site-packages/django/utils/functional.py", line 33, in __get__
    res = instance.__dict__[self.name] = self.func(instance)
  File "/Library/Python/2.7/site-packages/django/core/urlresolvers.py", line 417, in url_patterns
    patterns = getattr(self.urlconf_module, "urlpatterns", self.urlconf_module)
  File "/Library/Python/2.7/site-packages/django/utils/functional.py", line 33, in __get__
    res = instance.__dict__[self.name] = self.func(instance)
  File "/Library/Python/2.7/site-packages/django/core/urlresolvers.py", line 410, in urlconf_module
    return import_module(self.urlconf_name)
  File "/System/Library/Frameworks/Python.framework/Versions/2.7/lib/python2.7/importlib/__init__.py", line 37, in import_module
    __import__(name)
  File "/Users/Reetu/Documents/Projects/TargetDB/tgdbbackend/config/urls.py", line 27, in <module>
    url(r'^queryapp/', include('tgdbbackend.queryapp.urls', namespace='queryapp')),
  File "/Library/Python/2.7/site-packages/django/conf/urls/__init__.py", line 52, in include
    urlconf_module = import_module(urlconf_module)
  File "/System/Library/Frameworks/Python.framework/Versions/2.7/lib/python2.7/importlib/__init__.py", line 37, in import_module
    __import__(name)
  File "/Users/Reetu/Documents/Projects/TargetDB/tgdbbackend/tgdbbackend/queryapp/urls.py", line 4, in <module>
    from tgdbbackend.queryapp import views;
  File "/Users/Reetu/Documents/Projects/TargetDB/tgdbbackend/tgdbbackend/queryapp/views.py", line 7, in <module>
    from .app import query_TargetDB;
  File "/Users/Reetu/Documents/Projects/TargetDB/tgdbbackend/tgdbbackend/queryapp/app/query_TargetDB.py", line 36, in <module>
    import pathlib
ImportError: No module named pathlib
